<?xml version="1.0"?>
<robot xmlns:xacro="http://www.ros.org/wiki/xacro">

  <xacro:macro name="supre_robot">
    <!-- Used for fixing robot to Gazebo 'world' -->
    <link name="world"/>

    <joint name="base_joint" type="fixed">
        <parent link="world"/>
        <child link="base_link"/>
        <origin xyz="0 0 0" rpy="0 0 0"/>
    </joint>

    <link name="base_link">
        <visual>
            <geometry>
                <cylinder length="0.05" radius="0.2"/>
            </geometry>
            <material name="blue">
                <color rgba="0.0 0.0 1.0 1.0"/>
            </material>
        </visual>
        <collision>
            <geometry>
                <cylinder length="0.05" radius="0.2"/>
            </geometry>
        </collision>
    </link>
    
    <link name="gripper_finger_link">
        <visual>
            <geometry>
                <box size="0.1 0.02 0.02"/>
            </geometry>
        </visual>
        <collision>
            <geometry>
                <box size="0.1 0.02 0.02"/>
            </geometry>
        </collision>
        <inertial>
            <mass value="0.1"/>
            <inertia ixx="0.001" ixy="0" ixz="0" iyy="0.001" iyz="0" izz="0.001"/>
        </inertial>
    </link>

    <joint name="gripper_joint" type="prismatic">
        <parent link="base_link"/>
        <child link="gripper_finger_link"/>
        <origin xyz="0 0 0" rpy="0 0 0"/>
        <axis xyz="1 0 0"/>
        <limit lower="0.0" upper="0.025" effort="100" velocity="0.5"/>
    </joint>
  </xacro:macro>

</robot>